time 0ms: Simulator started for FCFS [Q <empty>]
time 0ms: Process A arrived and added to ready queue [Q A]
time 0ms: Process B arrived and added to ready queue [Q A B]
time 0ms: Process C arrived and added to ready queue [Q A B C]
time 0ms: Process X arrived and added to ready queue [Q A B C X]
time 0ms: Process Y arrived and added to ready queue [Q A B C X Y]
time 0ms: Process Z arrived and added to ready queue [Q A B C X Y Z]
time 3ms: Process A started using the CPU [Q B C X Y Z]
time 103ms: Process A completed a CPU burst; 4 bursts to go [Q B C X Y Z]
time 103ms: Process A switching out of CPU; will block on I/O until time 306ms [Q B C X Y Z]
time 109ms: Process B started using the CPU [Q C X Y Z]
time 210ms: Process B completed a CPU burst; 4 bursts to go [Q C X Y Z]
time 210ms: Process B switching out of CPU; will block on I/O until time 413ms [Q C X Y Z]
time 216ms: Process C started using the CPU [Q X Y Z]
time 306ms: Process A completed I/O; added to ready queue [Q X Y Z A]
time 318ms: Process C completed a CPU burst; 4 bursts to go [Q X Y Z A]
time 318ms: Process C switching out of CPU; will block on I/O until time 521ms [Q X Y Z A]
time 324ms: Process X started using the CPU [Q Y Z A]
time 413ms: Process B completed I/O; added to ready queue [Q Y Z A B]
time 427ms: Process X completed a CPU burst; 4 bursts to go [Q Y Z A B]
time 427ms: Process X switching out of CPU; will block on I/O until time 630ms [Q Y Z A B]
time 433ms: Process Y started using the CPU [Q Z A B]
time 521ms: Process C completed I/O; added to ready queue [Q Z A B C]
time 537ms: Process Y completed a CPU burst; 4 bursts to go [Q Z A B C]
time 537ms: Process Y switching out of CPU; will block on I/O until time 740ms [Q Z A B C]
time 543ms: Process Z started using the CPU [Q A B C]
time 630ms: Process X completed I/O; added to ready queue [Q A B C X]
time 648ms: Process Z completed a CPU burst; 4 bursts to go [Q A B C X]
time 648ms: Process Z switching out of CPU; will block on I/O until time 851ms [Q A B C X]
time 654ms: Process A started using the CPU [Q B C X]
time 740ms: Process Y completed I/O; added to ready queue [Q B C X Y]
time 754ms: Process A completed a CPU burst; 3 bursts to go [Q B C X Y]
time 754ms: Process A switching out of CPU; will block on I/O until time 957ms [Q B C X Y]
time 760ms: Process B started using the CPU [Q C X Y]
time 851ms: Process Z completed I/O; added to ready queue [Q C X Y Z]
time 861ms: Process B completed a CPU burst; 3 bursts to go [Q C X Y Z]
time 861ms: Process B switching out of CPU; will block on I/O until time 1064ms [Q C X Y Z]
time 867ms: Process C started using the CPU [Q X Y Z]
time 957ms: Process A completed I/O; added to ready queue [Q X Y Z A]
time 969ms: Process C completed a CPU burst; 3 bursts to go [Q X Y Z A]
time 969ms: Process C switching out of CPU; will block on I/O until time 1172ms [Q X Y Z A]
time 975ms: Process X started using the CPU [Q Y Z A]
time 1064ms: Process B completed I/O; added to ready queue [Q Y Z A B]
time 1078ms: Process X completed a CPU burst; 3 bursts to go [Q Y Z A B]
time 1078ms: Process X switching out of CPU; will block on I/O until time 1281ms [Q Y Z A B]
time 1084ms: Process Y started using the CPU [Q Z A B]
time 1172ms: Process C completed I/O; added to ready queue [Q Z A B C]
time 1188ms: Process Y completed a CPU burst; 3 bursts to go [Q Z A B C]
time 1188ms: Process Y switching out of CPU; will block on I/O until time 1391ms [Q Z A B C]
time 1194ms: Process Z started using the CPU [Q A B C]
time 1281ms: Process X completed I/O; added to ready queue [Q A B C X]
time 1299ms: Process Z completed a CPU burst; 3 bursts to go [Q A B C X]
time 1299ms: Process Z switching out of CPU; will block on I/O until time 1502ms [Q A B C X]
time 1305ms: Process A started using the CPU [Q B C X]
time 1391ms: Process Y completed I/O; added to ready queue [Q B C X Y]
time 1405ms: Process A completed a CPU burst; 2 bursts to go [Q B C X Y]
time 1405ms: Process A switching out of CPU; will block on I/O until time 1608ms [Q B C X Y]
time 1411ms: Process B started using the CPU [Q C X Y]
time 1502ms: Process Z completed I/O; added to ready queue [Q C X Y Z]
time 1512ms: Process B completed a CPU burst; 2 bursts to go [Q C X Y Z]
time 1512ms: Process B switching out of CPU; will block on I/O until time 1715ms [Q C X Y Z]
time 1518ms: Process C started using the CPU [Q X Y Z]
time 1608ms: Process A completed I/O; added to ready queue [Q X Y Z A]
time 1620ms: Process C completed a CPU burst; 2 bursts to go [Q X Y Z A]
time 1620ms: Process C switching out of CPU; will block on I/O until time 1823ms [Q X Y Z A]
time 1626ms: Process X started using the CPU [Q Y Z A]
time 1715ms: Process B completed I/O; added to ready queue [Q Y Z A B]
time 1729ms: Process X completed a CPU burst; 2 bursts to go [Q Y Z A B]
time 1729ms: Process X switching out of CPU; will block on I/O until time 1932ms [Q Y Z A B]
time 1735ms: Process Y started using the CPU [Q Z A B]
time 1823ms: Process C completed I/O; added to ready queue [Q Z A B C]
time 1839ms: Process Y completed a CPU burst; 2 bursts to go [Q Z A B C]
time 1839ms: Process Y switching out of CPU; will block on I/O until time 2042ms [Q Z A B C]
time 1845ms: Process Z started using the CPU [Q A B C]
time 1932ms: Process X completed I/O; added to ready queue [Q A B C X]
time 1950ms: Process Z completed a CPU burst; 2 bursts to go [Q A B C X]
time 1950ms: Process Z switching out of CPU; will block on I/O until time 2153ms [Q A B C X]
time 1956ms: Process A started using the CPU [Q B C X]
time 2042ms: Process Y completed I/O; added to ready queue [Q B C X Y]
time 2056ms: Process A completed a CPU burst; 1 burst to go [Q B C X Y]
time 2056ms: Process A switching out of CPU; will block on I/O until time 2259ms [Q B C X Y]
time 2062ms: Process B started using the CPU [Q C X Y]
time 2153ms: Process Z completed I/O; added to ready queue [Q C X Y Z]
time 2163ms: Process B completed a CPU burst; 1 burst to go [Q C X Y Z]
time 2163ms: Process B switching out of CPU; will block on I/O until time 2366ms [Q C X Y Z]
time 2169ms: Process C started using the CPU [Q X Y Z]
time 2259ms: Process A completed I/O; added to ready queue [Q X Y Z A]
time 2271ms: Process C completed a CPU burst; 1 burst to go [Q X Y Z A]
time 2271ms: Process C switching out of CPU; will block on I/O until time 2474ms [Q X Y Z A]
time 2277ms: Process X started using the CPU [Q Y Z A]
time 2366ms: Process B completed I/O; added to ready queue [Q Y Z A B]
time 2380ms: Process X completed a CPU burst; 1 burst to go [Q Y Z A B]
time 2380ms: Process X switching out of CPU; will block on I/O until time 2583ms [Q Y Z A B]
time 2386ms: Process Y started using the CPU [Q Z A B]
time 2474ms: Process C completed I/O; added to ready queue [Q Z A B C]
time 2490ms: Process Y completed a CPU burst; 1 burst to go [Q Z A B C]
time 2490ms: Process Y switching out of CPU; will block on I/O until time 2693ms [Q Z A B C]
time 2496ms: Process Z started using the CPU [Q A B C]
time 2583ms: Process X completed I/O; added to ready queue [Q A B C X]
time 2601ms: Process Z completed a CPU burst; 1 burst to go [Q A B C X]
time 2601ms: Process Z switching out of CPU; will block on I/O until time 2804ms [Q A B C X]
time 2607ms: Process A started using the CPU [Q B C X]
time 2693ms: Process Y completed I/O; added to ready queue [Q B C X Y]
time 2707ms: Process A terminated [Q B C X Y]
time 2713ms: Process B started using the CPU [Q C X Y]
time 2804ms: Process Z completed I/O; added to ready queue [Q C X Y Z]
time 2814ms: Process B terminated [Q C X Y Z]
time 2820ms: Process C started using the CPU [Q X Y Z]
time 2922ms: Process C terminated [Q X Y Z]
time 2928ms: Process X started using the CPU [Q Y Z]
time 3031ms: Process X terminated [Q Y Z]
time 3037ms: Process Y started using the CPU [Q Z]
time 3141ms: Process Y terminated [Q Z]
time 3147ms: Process Z started using the CPU [Q <empty>]
time 3252ms: Process Z terminated [Q <empty>]
time 3255ms: Simulator ended for FCFS
