time 0ms: Simulator started for FCFS [Q <empty>]
time 0ms: Process X arrived and added to ready queue [Q X]
time 0ms: Process Y arrived and added to ready queue [Q X Y]
time 0ms: Process Z arrived and added to ready queue [Q X Y Z]
time 3ms: Process X started using the CPU [Q Y Z]
time 759ms: Process X completed a CPU burst; 4 bursts to go [Q Y Z]
time 759ms: Process X switching out of CPU; will block on I/O until time 782ms [Q Y Z]
time 765ms: Process Y started using the CPU [Q Z]
time 782ms: Process X completed I/O; added to ready queue [Q Z X]
time 1605ms: Process Y completed a CPU burst; 4 bursts to go [Q Z X]
time 1605ms: Process Y switching out of CPU; will block on I/O until time 1628ms [Q Z X]
time 1611ms: Process Z started using the CPU [Q X]
time 1628ms: Process Y completed I/O; added to ready queue [Q X Y]
time 2535ms: Process Z completed a CPU burst; 4 bursts to go [Q X Y]
time 2535ms: Process Z switching out of CPU; will block on I/O until time 2558ms [Q X Y]
time 2541ms: Process X started using the CPU [Q Y]
time 2558ms: Process Z completed I/O; added to ready queue [Q Y Z]
time 3297ms: Process X completed a CPU burst; 3 bursts to go [Q Y Z]
time 3297ms: Process X switching out of CPU; will block on I/O until time 3320ms [Q Y Z]
time 3303ms: Process Y started using the CPU [Q Z]
time 3320ms: Process X completed I/O; added to ready queue [Q Z X]
time 4143ms: Process Y completed a CPU burst; 3 bursts to go [Q Z X]
time 4143ms: Process Y switching out of CPU; will block on I/O until time 4166ms [Q Z X]
time 4149ms: Process Z started using the CPU [Q X]
time 4166ms: Process Y completed I/O; added to ready queue [Q X Y]
time 5073ms: Process Z completed a CPU burst; 3 bursts to go [Q X Y]
time 5073ms: Process Z switching out of CPU; will block on I/O until time 5096ms [Q X Y]
time 5079ms: Process X started using the CPU [Q Y]
time 5096ms: Process Z completed I/O; added to ready queue [Q Y Z]
time 5835ms: Process X completed a CPU burst; 2 bursts to go [Q Y Z]
time 5835ms: Process X switching out of CPU; will block on I/O until time 5858ms [Q Y Z]
time 5841ms: Process Y started using the CPU [Q Z]
time 5858ms: Process X completed I/O; added to ready queue [Q Z X]
time 6681ms: Process Y completed a CPU burst; 2 bursts to go [Q Z X]
time 6681ms: Process Y switching out of CPU; will block on I/O until time 6704ms [Q Z X]
time 6687ms: Process Z started using the CPU [Q X]
time 6704ms: Process Y completed I/O; added to ready queue [Q X Y]
time 7611ms: Process Z completed a CPU burst; 2 bursts to go [Q X Y]
time 7611ms: Process Z switching out of CPU; will block on I/O until time 7634ms [Q X Y]
time 7617ms: Process X started using the CPU [Q Y]
time 7634ms: Process Z completed I/O; added to ready queue [Q Y Z]
time 8373ms: Process X completed a CPU burst; 1 burst to go [Q Y Z]
time 8373ms: Process X switching out of CPU; will block on I/O until time 8396ms [Q Y Z]
time 8379ms: Process Y started using the CPU [Q Z]
time 8396ms: Process X completed I/O; added to ready queue [Q Z X]
time 9219ms: Process Y completed a CPU burst; 1 burst to go [Q Z X]
time 9219ms: Process Y switching out of CPU; will block on I/O until time 9242ms [Q Z X]
time 9225ms: Process Z started using the CPU [Q X]
time 9242ms: Process Y completed I/O; added to ready queue [Q X Y]
time 10149ms: Process Z completed a CPU burst; 1 burst to go [Q X Y]
time 10149ms: Process Z switching out of CPU; will block on I/O until time 10172ms [Q X Y]
time 10155ms: Process X started using the CPU [Q Y]
time 10172ms: Process Z completed I/O; added to ready queue [Q Y Z]
time 10911ms: Process X terminated [Q Y Z]
time 10917ms: Process Y started using the CPU [Q Z]
time 11757ms: Process Y terminated [Q Z]
time 11763ms: Process Z started using the CPU [Q <empty>]
time 12687ms: Process Z terminated [Q <empty>]
time 12690ms: Simulator ended for FCFS
