time 0ms: Simulator started for FCFS [Q <empty>]
time 0ms: Process T arrived and added to ready queue [Q T]
time 3ms: Process T started using the CPU [Q <empty>]
time 20ms: Process U arrived and added to ready queue [Q U]
time 190ms: Process V arrived and added to ready queue [Q U V]
time 843ms: Process T completed a CPU burst; 4 bursts to go [Q U V]
time 843ms: Process T switching out of CPU; will block on I/O until time 866ms [Q U V]
time 849ms: Process U started using the CPU [Q V]
time 866ms: Process T completed I/O; added to ready queue [Q V T]
time 1189ms: Process U completed a CPU burst; 4 bursts to go [Q V T]
time 1189ms: Process U switching out of CPU; will block on I/O until time 1232ms [Q V T]
time 1195ms: Process V started using the CPU [Q T]
time 1232ms: Process U completed I/O; added to ready queue [Q T U]
time 2135ms: Process V completed a CPU burst; 4 bursts to go [Q T U]
time 2135ms: Process V switching out of CPU; will block on I/O until time 2168ms [Q T U]
time 2141ms: Process T started using the CPU [Q U]
time 2168ms: Process V completed I/O; added to ready queue [Q U V]
time 2981ms: Process T completed a CPU burst; 3 bursts to go [Q U V]
time 2981ms: Process T switching out of CPU; will block on I/O until time 3004ms [Q U V]
time 2987ms: Process U started using the CPU [Q V]
time 3004ms: Process T completed I/O; added to ready queue [Q V T]
time 3327ms: Process U completed a CPU burst; 3 bursts to go [Q V T]
time 3327ms: Process U switching out of CPU; will block on I/O until time 3370ms [Q V T]
time 3333ms: Process V started using the CPU [Q T]
time 3370ms: Process U completed I/O; added to ready queue [Q T U]
time 4273ms: Process V completed a CPU burst; 3 bursts to go [Q T U]
time 4273ms: Process V switching out of CPU; will block on I/O until time 4306ms [Q T U]
time 4279ms: Process T started using the CPU [Q U]
time 4306ms: Process V completed I/O; added to ready queue [Q U V]
time 5119ms: Process T completed a CPU burst; 2 bursts to go [Q U V]
time 5119ms: Process T switching out of CPU; will block on I/O until time 5142ms [Q U V]
time 5125ms: Process U started using the CPU [Q V]
time 5142ms: Process T completed I/O; added to ready queue [Q V T]
time 5465ms: Process U completed a CPU burst; 2 bursts to go [Q V T]
time 5465ms: Process U switching out of CPU; will block on I/O until time 5508ms [Q V T]
time 5471ms: Process V started using the CPU [Q T]
time 5508ms: Process U completed I/O; added to ready queue [Q T U]
time 6411ms: Process V completed a CPU burst; 2 bursts to go [Q T U]
time 6411ms: Process V switching out of CPU; will block on I/O until time 6444ms [Q T U]
time 6417ms: Process T started using the CPU [Q U]
time 6444ms: Process V completed I/O; added to ready queue [Q U V]
time 7257ms: Process T completed a CPU burst; 1 burst to go [Q U V]
time 7257ms: Process T switching out of CPU; will block on I/O until time 7280ms [Q U V]
time 7263ms: Process U started using the CPU [Q V]
time 7280ms: Process T completed I/O; added to ready queue [Q V T]
time 7603ms: Process U completed a CPU burst; 1 burst to go [Q V T]
time 7603ms: Process U switching out of CPU; will block on I/O until time 7646ms [Q V T]
time 7609ms: Process V started using the CPU [Q T]
time 7646ms: Process U completed I/O; added to ready queue [Q T U]
time 8549ms: Process V completed a CPU burst; 1 burst to go [Q T U]
time 8549ms: Process V switching out of CPU; will block on I/O until time 8582ms [Q T U]
time 8555ms: Process T started using the CPU [Q U]
time 8582ms: Process V completed I/O; added to ready queue [Q U V]
time 9395ms: Process T terminated [Q U V]
time 9401ms: Process U started using the CPU [Q V]
time 9741ms: Process U terminated [Q V]
time 9747ms: Process V started using the CPU [Q <empty>]
time 10687ms: Process V terminated [Q <empty>]
time 10690ms: Simulator ended for FCFS
