time 0ms: Simulator started for FCFS [Q <empty>]
time 0ms: Process A arrived and added to ready queue [Q A]
time 0ms: Process B arrived and added to ready queue [Q A B]
time 3ms: Process A started using the CPU [Q B]
time 171ms: Process A completed a CPU burst; 4 bursts to go [Q B]
time 171ms: Process A switching out of CPU; will block on I/O until time 461ms [Q B]
time 177ms: Process B started using the CPU [Q <empty>]
time 190ms: Process C arrived and added to ready queue [Q C]
time 250ms: Process D arrived and added to ready queue [Q C D]
time 461ms: Process A completed I/O; added to ready queue [Q C D A]
time 562ms: Process B terminated [Q C D A]
time 568ms: Process C started using the CPU [Q D A]
time 665ms: Process C completed a CPU burst; 4 bursts to go [Q D A]
time 665ms: Process C switching out of CPU; will block on I/O until time 3167ms [Q D A]
time 671ms: Process D started using the CPU [Q A]
time 2441ms: Process D completed a CPU burst; 1 burst to go [Q A]
time 2441ms: Process D switching out of CPU; will block on I/O until time 3266ms [Q A]
time 2447ms: Process A started using the CPU [Q <empty>]
time 2615ms: Process A completed a CPU burst; 3 bursts to go [Q <empty>]
time 2615ms: Process A switching out of CPU; will block on I/O until time 2905ms [Q <empty>]
time 2905ms: Process A completed I/O; added to ready queue [Q A]
time 2908ms: Process A started using the CPU [Q <empty>]
time 3076ms: Process A completed a CPU burst; 2 bursts to go [Q <empty>]
time 3076ms: Process A switching out of CPU; will block on I/O until time 3366ms [Q <empty>]
time 3167ms: Process C completed I/O; added to ready queue [Q C]
time 3170ms: Process C started using the CPU [Q <empty>]
time 3266ms: Process D completed I/O; added to ready queue [Q D]
time 3267ms: Process C completed a CPU burst; 3 bursts to go [Q D]
time 3267ms: Process C switching out of CPU; will block on I/O until time 5769ms [Q D]
time 3273ms: Process D started using the CPU [Q <empty>]
time 3366ms: Process A completed I/O; added to ready queue [Q A]
time 5043ms: Process D terminated [Q A]
time 5049ms: Process A started using the CPU [Q <empty>]
time 5217ms: Process A completed a CPU burst; 1 burst to go [Q <empty>]
time 5217ms: Process A switching out of CPU; will block on I/O until time 5507ms [Q <empty>]
time 5507ms: Process A completed I/O; added to ready queue [Q A]
time 5510ms: Process A started using the CPU [Q <empty>]
time 5678ms: Process A terminated [Q <empty>]
time 5769ms: Process C completed I/O; added to ready queue [Q C]
time 5772ms: Process C started using the CPU [Q <empty>]
time 5869ms: Process C completed a CPU burst; 2 bursts to go [Q <empty>]
time 5869ms: Process C switching out of CPU; will block on I/O until time 8371ms [Q <empty>]
time 8371ms: Process C completed I/O; added to ready queue [Q C]
time 8374ms: Process C started using the CPU [Q <empty>]
time 8471ms: Process C completed a CPU burst; 1 burst to go [Q <empty>]
time 8471ms: Process C switching out of CPU; will block on I/O until time 10973ms [Q <empty>]
time 10973ms: Process C completed I/O; added to ready queue [Q C]
time 10976ms: Process C started using the CPU [Q <empty>]
time 11073ms: Process C terminated [Q <empty>]
time 11076ms: Simulator ended for FCFS
